Internal Server Error: /api/auth/register/
Traceback (most recent call last):
  File "C:\Users\willk\WebstormProjects\Grey-De-Site\venv\Lib\site-packages\django\core\handlers\exception.py", line 55, in inner
    response = get_response(request)
  File "C:\Users\willk\WebstormProjects\Grey-De-Site\venv\Lib\site-packages\django\core\handlers\base.py", line 197, in _get_response
    response = wrapped_callback(request, *callback_args, **callback_kwargs)
  File "C:\Users\willk\WebstormProjects\Grey-De-Site\venv\Lib\site-packages\django\views\decorators\csrf.py", line 65, in _view_wrapper
    return view_func(request, *args, **kwargs)
  File "C:\Users\willk\WebstormProjects\Grey-De-Site\venv\Lib\site-packages\django\views\generic\base.py", line 104, in view
    return self.dispatch(request, *args, **kwargs)
           ~~~~~~~~~~~~~^^^^^^^^^^^^^^^^^^^^^^^^^^
  File "C:\Users\willk\WebstormProjects\Grey-De-Site\venv\Lib\site-packages\rest_framework\views.py", line 509, in dispatch
    response = self.handle_exception(exc)
  File "C:\Users\willk\WebstormProjects\Grey-De-Site\venv\Lib\site-packages\rest_framework\views.py", line 469, in handle_exception
    self.raise_uncaught_exception(exc)
    ~~~~~~~~~~~~~~~~~~~~~~~~~~~~~^^^^^
  File "C:\Users\willk\WebstormProjects\Grey-De-Site\venv\Lib\site-packages\rest_framework\views.py", line 480, in raise_uncaught_exception
    raise exc
  File "C:\Users\willk\WebstormProjects\Grey-De-Site\venv\Lib\site-packages\rest_framework\views.py", line 506, in dispatch
    response = handler(request, *args, **kwargs)
  File "C:\Users\willk\WebstormProjects\Grey-De-Site\venv\Lib\site-packages\rest_framework\decorators.py", line 50, in handler
    return func(*args, **kwargs)
  File "C:\Users\willk\WebstormProjects\Grey-De-Site\backend\accounts\views.py", line 13, in register
    if serializer.is_valid():
       ~~~~~~~~~~~~~~~~~~~^^
  File "C:\Users\willk\WebstormProjects\Grey-De-Site\venv\Lib\site-packages\rest_framework\serializers.py", line 223, in is_valid
    self._validated_data = self.run_validation(self.initial_data)
                           ~~~~~~~~~~~~~~~~~~~^^^^^^^^^^^^^^^^^^^
  File "C:\Users\willk\WebstormProjects\Grey-De-Site\venv\Lib\site-packages\rest_framework\serializers.py", line 442, in run_validation
    value = self.to_internal_value(data)
  File "C:\Users\willk\WebstormProjects\Grey-De-Site\venv\Lib\site-packages\rest_framework\serializers.py", line 495, in to_internal_value
    for field in fields:
                 ^^^^^^
  File "C:\Users\willk\WebstormProjects\Grey-De-Site\venv\Lib\site-packages\rest_framework\serializers.py", line 378, in _writable_fields
    for field in self.fields.values():
                 ^^^^^^^^^^^
  File "C:\Users\willk\WebstormProjects\Grey-De-Site\venv\Lib\site-packages\django\utils\functional.py", line 47, in __get__
    res = instance.__dict__[self.name] = self.func(instance)
                                         ~~~~~~~~~^^^^^^^^^^
  File "C:\Users\willk\WebstormProjects\Grey-De-Site\venv\Lib\site-packages\rest_framework\serializers.py", line 372, in fields
    for key, value in self.get_fields().items():
                      ~~~~~~~~~~~~~~~^^
  File "C:\Users\willk\WebstormProjects\Grey-De-Site\venv\Lib\site-packages\rest_framework\serializers.py", line 1103, in get_fields
    field_class, field_kwargs = self.build_field(
                                ~~~~~~~~~~~~~~~~^
        source, info, model, depth
        ^^^^^^^^^^^^^^^^^^^^^^^^^^
    )
    ^
  File "C:\Users\willk\WebstormProjects\Grey-De-Site\venv\Lib\site-packages\rest_framework\serializers.py", line 1249, in build_field
    return self.build_unknown_field(field_name, model_class)
           ~~~~~~~~~~~~~~~~~~~~~~~~^^^^^^^^^^^^^^^^^^^^^^^^^
  File "C:\Users\willk\WebstormProjects\Grey-De-Site\venv\Lib\site-packages\rest_framework\serializers.py", line 1367, in build_unknown_field
    raise ImproperlyConfigured(
    ...<2 lines>...
    )
django.core.exceptions.ImproperlyConfigured: Field name `role` is not valid for model `User` in `accounts.serializers.RegisterSerializer`.
"POST /api/auth/register/ HTTP/1.1" 500 145
Internal Server Error: /api/auth/register/
Traceback (most recent call last):
  File "C:\Users\willk\WebstormProjects\Grey-De-Site\venv\Lib\site-packages\django\core\handlers\exception.py", line 55, in inner
    response = get_response(request)
  File "C:\Users\willk\WebstormProjects\Grey-De-Site\venv\Lib\site-packages\django\core\handlers\base.py", line 197, in _get_response
    response = wrapped_callback(request, *callback_args, **callback_kwargs)
  File "C:\Users\willk\WebstormProjects\Grey-De-Site\venv\Lib\site-packages\django\views\decorators\csrf.py", line 65, in _view_wrapper
    return view_func(request, *args, **kwargs)
  File "C:\Users\willk\WebstormProjects\Grey-De-Site\venv\Lib\site-packages\django\views\generic\base.py", line 104, in view
    return self.dispatch(request, *args, **kwargs)
           ~~~~~~~~~~~~~^^^^^^^^^^^^^^^^^^^^^^^^^^
  File "C:\Users\willk\WebstormProjects\Grey-De-Site\venv\Lib\site-packages\rest_framework\views.py", line 509, in dispatch
    response = self.handle_exception(exc)
  File "C:\Users\willk\WebstormProjects\Grey-De-Site\venv\Lib\site-packages\rest_framework\views.py", line 469, in handle_exception
    self.raise_uncaught_exception(exc)
    ~~~~~~~~~~~~~~~~~~~~~~~~~~~~~^^^^^
  File "C:\Users\willk\WebstormProjects\Grey-De-Site\venv\Lib\site-packages\rest_framework\views.py", line 480, in raise_uncaught_exception
    raise exc
  File "C:\Users\willk\WebstormProjects\Grey-De-Site\venv\Lib\site-packages\rest_framework\views.py", line 506, in dispatch
    response = handler(request, *args, **kwargs)
  File "C:\Users\willk\WebstormProjects\Grey-De-Site\venv\Lib\site-packages\rest_framework\decorators.py", line 50, in handler
    return func(*args, **kwargs)
  File "C:\Users\willk\WebstormProjects\Grey-De-Site\backend\accounts\views.py", line 13, in register
    if serializer.is_valid():
       ~~~~~~~~~~~~~~~~~~~^^
  File "C:\Users\willk\WebstormProjects\Grey-De-Site\venv\Lib\site-packages\rest_framework\serializers.py", line 223, in is_valid
    self._validated_data = self.run_validation(self.initial_data)
                           ~~~~~~~~~~~~~~~~~~~^^^^^^^^^^^^^^^^^^^
  File "C:\Users\willk\WebstormProjects\Grey-De-Site\venv\Lib\site-packages\rest_framework\serializers.py", line 442, in run_validation
    value = self.to_internal_value(data)
  File "C:\Users\willk\WebstormProjects\Grey-De-Site\venv\Lib\site-packages\rest_framework\serializers.py", line 495, in to_internal_value
    for field in fields:
                 ^^^^^^
  File "C:\Users\willk\WebstormProjects\Grey-De-Site\venv\Lib\site-packages\rest_framework\serializers.py", line 378, in _writable_fields
    for field in self.fields.values():
                 ^^^^^^^^^^^
  File "C:\Users\willk\WebstormProjects\Grey-De-Site\venv\Lib\site-packages\django\utils\functional.py", line 47, in __get__
    res = instance.__dict__[self.name] = self.func(instance)
                                         ~~~~~~~~~^^^^^^^^^^
  File "C:\Users\willk\WebstormProjects\Grey-De-Site\venv\Lib\site-packages\rest_framework\serializers.py", line 372, in fields
    for key, value in self.get_fields().items():
                      ~~~~~~~~~~~~~~~^^
  File "C:\Users\willk\WebstormProjects\Grey-De-Site\venv\Lib\site-packages\rest_framework\serializers.py", line 1103, in get_fields
    field_class, field_kwargs = self.build_field(
                                ~~~~~~~~~~~~~~~~^
        source, info, model, depth
        ^^^^^^^^^^^^^^^^^^^^^^^^^^
    )
    ^
  File "C:\Users\willk\WebstormProjects\Grey-De-Site\venv\Lib\site-packages\rest_framework\serializers.py", line 1249, in build_field
    return self.build_unknown_field(field_name, model_class)
           ~~~~~~~~~~~~~~~~~~~~~~~~^^^^^^^^^^^^^^^^^^^^^^^^^
  File "C:\Users\willk\WebstormProjects\Grey-De-Site\venv\Lib\site-packages\rest_framework\serializers.py", line 1367, in build_unknown_field
    raise ImproperlyConfigured(
    ...<2 lines>...
    )
django.core.exceptions.ImproperlyConfigured: Field name `role` is not valid for model `User` in `accounts.serializers.RegisterSerializer`.
"POST /api/auth/register/ HTTP/1.1" 500 145
Internal Server Error: /api/auth/register/
Traceback (most recent call last):
  File "C:\Users\willk\WebstormProjects\Grey-De-Site\venv\Lib\site-packages\django\core\handlers\exception.py", line 55, in inner
    response = get_response(request)
  File "C:\Users\willk\WebstormProjects\Grey-De-Site\venv\Lib\site-packages\django\core\handlers\base.py", line 197, in _get_response
    response = wrapped_callback(request, *callback_args, **callback_kwargs)
  File "C:\Users\willk\WebstormProjects\Grey-De-Site\venv\Lib\site-packages\django\views\decorators\csrf.py", line 65, in _view_wrapper
    return view_func(request, *args, **kwargs)
  File "C:\Users\willk\WebstormProjects\Grey-De-Site\venv\Lib\site-packages\django\views\generic\base.py", line 104, in view
    return self.dispatch(request, *args, **kwargs)
           ~~~~~~~~~~~~~^^^^^^^^^^^^^^^^^^^^^^^^^^
  File "C:\Users\willk\WebstormProjects\Grey-De-Site\venv\Lib\site-packages\rest_framework\views.py", line 509, in dispatch
    response = self.handle_exception(exc)
  File "C:\Users\willk\WebstormProjects\Grey-De-Site\venv\Lib\site-packages\rest_framework\views.py", line 469, in handle_exception
    self.raise_uncaught_exception(exc)
    ~~~~~~~~~~~~~~~~~~~~~~~~~~~~~^^^^^
  File "C:\Users\willk\WebstormProjects\Grey-De-Site\venv\Lib\site-packages\rest_framework\views.py", line 480, in raise_uncaught_exception
    raise exc
  File "C:\Users\willk\WebstormProjects\Grey-De-Site\venv\Lib\site-packages\rest_framework\views.py", line 506, in dispatch
    response = handler(request, *args, **kwargs)
  File "C:\Users\willk\WebstormProjects\Grey-De-Site\venv\Lib\site-packages\rest_framework\decorators.py", line 50, in handler
    return func(*args, **kwargs)
  File "C:\Users\willk\WebstormProjects\Grey-De-Site\backend\accounts\views.py", line 13, in register
    if serializer.is_valid():
       ~~~~~~~~~~~~~~~~~~~^^
  File "C:\Users\willk\WebstormProjects\Grey-De-Site\venv\Lib\site-packages\rest_framework\serializers.py", line 223, in is_valid
    self._validated_data = self.run_validation(self.initial_data)
                           ~~~~~~~~~~~~~~~~~~~^^^^^^^^^^^^^^^^^^^
  File "C:\Users\willk\WebstormProjects\Grey-De-Site\venv\Lib\site-packages\rest_framework\serializers.py", line 442, in run_validation
    value = self.to_internal_value(data)
  File "C:\Users\willk\WebstormProjects\Grey-De-Site\venv\Lib\site-packages\rest_framework\serializers.py", line 495, in to_internal_value
    for field in fields:
                 ^^^^^^
  File "C:\Users\willk\WebstormProjects\Grey-De-Site\venv\Lib\site-packages\rest_framework\serializers.py", line 378, in _writable_fields
    for field in self.fields.values():
                 ^^^^^^^^^^^
  File "C:\Users\willk\WebstormProjects\Grey-De-Site\venv\Lib\site-packages\django\utils\functional.py", line 47, in __get__
    res = instance.__dict__[self.name] = self.func(instance)
                                         ~~~~~~~~~^^^^^^^^^^
  File "C:\Users\willk\WebstormProjects\Grey-De-Site\venv\Lib\site-packages\rest_framework\serializers.py", line 372, in fields
    for key, value in self.get_fields().items():
                      ~~~~~~~~~~~~~~~^^
  File "C:\Users\willk\WebstormProjects\Grey-De-Site\venv\Lib\site-packages\rest_framework\serializers.py", line 1103, in get_fields
    field_class, field_kwargs = self.build_field(
                                ~~~~~~~~~~~~~~~~^
        source, info, model, depth
        ^^^^^^^^^^^^^^^^^^^^^^^^^^
    )
    ^
  File "C:\Users\willk\WebstormProjects\Grey-De-Site\venv\Lib\site-packages\rest_framework\serializers.py", line 1249, in build_field
    return self.build_unknown_field(field_name, model_class)
           ~~~~~~~~~~~~~~~~~~~~~~~~^^^^^^^^^^^^^^^^^^^^^^^^^
  File "C:\Users\willk\WebstormProjects\Grey-De-Site\venv\Lib\site-packages\rest_framework\serializers.py", line 1367, in build_unknown_field
    raise ImproperlyConfigured(
    ...<2 lines>...
    )
django.core.exceptions.ImproperlyConfigured: Field name `role` is not valid for model `User` in `accounts.serializers.RegisterSerializer`.
"POST /api/auth/register/ HTTP/1.1" 500 145
Internal Server Error: /api/auth/register/
Traceback (most recent call last):
  File "C:\Users\willk\WebstormProjects\Grey-De-Site\venv\Lib\site-packages\django\core\handlers\exception.py", line 55, in inner
    response = get_response(request)
  File "C:\Users\willk\WebstormProjects\Grey-De-Site\venv\Lib\site-packages\django\core\handlers\base.py", line 197, in _get_response
    response = wrapped_callback(request, *callback_args, **callback_kwargs)
  File "C:\Users\willk\WebstormProjects\Grey-De-Site\venv\Lib\site-packages\django\views\decorators\csrf.py", line 65, in _view_wrapper
    return view_func(request, *args, **kwargs)
  File "C:\Users\willk\WebstormProjects\Grey-De-Site\venv\Lib\site-packages\django\views\generic\base.py", line 104, in view
    return self.dispatch(request, *args, **kwargs)
           ~~~~~~~~~~~~~^^^^^^^^^^^^^^^^^^^^^^^^^^
  File "C:\Users\willk\WebstormProjects\Grey-De-Site\venv\Lib\site-packages\rest_framework\views.py", line 509, in dispatch
    response = self.handle_exception(exc)
  File "C:\Users\willk\WebstormProjects\Grey-De-Site\venv\Lib\site-packages\rest_framework\views.py", line 469, in handle_exception
    self.raise_uncaught_exception(exc)
    ~~~~~~~~~~~~~~~~~~~~~~~~~~~~~^^^^^
  File "C:\Users\willk\WebstormProjects\Grey-De-Site\venv\Lib\site-packages\rest_framework\views.py", line 480, in raise_uncaught_exception
    raise exc
  File "C:\Users\willk\WebstormProjects\Grey-De-Site\venv\Lib\site-packages\rest_framework\views.py", line 506, in dispatch
    response = handler(request, *args, **kwargs)
  File "C:\Users\willk\WebstormProjects\Grey-De-Site\venv\Lib\site-packages\rest_framework\decorators.py", line 50, in handler
    return func(*args, **kwargs)
  File "C:\Users\willk\WebstormProjects\Grey-De-Site\backend\accounts\views.py", line 13, in register
    if serializer.is_valid():
       ~~~~~~~~~~~~~~~~~~~^^
  File "C:\Users\willk\WebstormProjects\Grey-De-Site\venv\Lib\site-packages\rest_framework\serializers.py", line 223, in is_valid
    self._validated_data = self.run_validation(self.initial_data)
                           ~~~~~~~~~~~~~~~~~~~^^^^^^^^^^^^^^^^^^^
  File "C:\Users\willk\WebstormProjects\Grey-De-Site\venv\Lib\site-packages\rest_framework\serializers.py", line 442, in run_validation
    value = self.to_internal_value(data)
  File "C:\Users\willk\WebstormProjects\Grey-De-Site\venv\Lib\site-packages\rest_framework\serializers.py", line 495, in to_internal_value
    for field in fields:
                 ^^^^^^
  File "C:\Users\willk\WebstormProjects\Grey-De-Site\venv\Lib\site-packages\rest_framework\serializers.py", line 378, in _writable_fields
    for field in self.fields.values():
                 ^^^^^^^^^^^
  File "C:\Users\willk\WebstormProjects\Grey-De-Site\venv\Lib\site-packages\django\utils\functional.py", line 47, in __get__
    res = instance.__dict__[self.name] = self.func(instance)
                                         ~~~~~~~~~^^^^^^^^^^
  File "C:\Users\willk\WebstormProjects\Grey-De-Site\venv\Lib\site-packages\rest_framework\serializers.py", line 372, in fields
    for key, value in self.get_fields().items():
                      ~~~~~~~~~~~~~~~^^
  File "C:\Users\willk\WebstormProjects\Grey-De-Site\venv\Lib\site-packages\rest_framework\serializers.py", line 1103, in get_fields
    field_class, field_kwargs = self.build_field(
                                ~~~~~~~~~~~~~~~~^
        source, info, model, depth
        ^^^^^^^^^^^^^^^^^^^^^^^^^^
    )
    ^
  File "C:\Users\willk\WebstormProjects\Grey-De-Site\venv\Lib\site-packages\rest_framework\serializers.py", line 1249, in build_field
    return self.build_unknown_field(field_name, model_class)
           ~~~~~~~~~~~~~~~~~~~~~~~~^^^^^^^^^^^^^^^^^^^^^^^^^
  File "C:\Users\willk\WebstormProjects\Grey-De-Site\venv\Lib\site-packages\rest_framework\serializers.py", line 1367, in build_unknown_field
    raise ImproperlyConfigured(
    ...<2 lines>...
    )
django.core.exceptions.ImproperlyConfigured: Field name `role` is not valid for model `User` in `accounts.serializers.RegisterSerializer`.
"POST /api/auth/register/ HTTP/1.1" 500 145
